Workbook

Sheet RubricTutor
D1: Bachelor's degree in Techniques for Software Application Development
D2: =CONCATENATE(Language!C13, D7) -> Trabajo final - Semestre 2025-1
A4: =Language!C5 -> Nombre del/de la estudiante:
A5: =Language!C6 -> Título del trabajo:
A6: =Language!C7 -> Programa: | D6: Bachelor's degree in Techniques for Software Application Development
A7: =Language!C8 -> Semestre: | D7: 2025-1
A8: =Language!C9 -> Tutor/a:
A9: =Language!C10 -> Evaluador/a 1:
A10: =Language!C11 -> Evaluador/a 2:
A11: =Language!C12 -> Evaluador/a 3:
A13: A | C13: B | E13: C+ | G13: C- | K13: D
A14: 10 | B14: 9 | C14: 8 | D14: 7 | E14: 6 | F14: 5 | G14: 4 | I14: 3 | K14: 2 | M14: 1 | O14: 0
A16: =Language!C14 -> Evaluación del tutor/a | G16: =Language!C20 -> PEC1: Propuesta inicial y planificación | I16: =Language!C21 -> PEC2: Desarrollo del proyecto | K16: =Language!C22 -> PEC3: Desarrollo del proyecto | M16: =Language!C23 -> PEC 4: Entrega final | Q16: =Language!C24 -> Notas finales de la evaluación del tutor/a
A17: =Language!C29 -> Actitud del/de la estudiante | G17: =Language!C25 -> Peso | H17: Nota | I17: =Language!C25 -> Peso | J17: Nota | K17: =Language!C25 -> Peso | L17: Nota | M17: =Language!C25 -> Peso | N17: Nota | O17: =Language!C25 -> Peso | P17: Nota | Q17: Final | S17: =Language!C75 -> % peso nota final
A18: =Language!C30 -> Grado de autonomía, creatividad, iniciativa, receptividad a la crítica, y buena comunicación con el tutor/a | G18: 1 | H18: N | I18: 1 | J18: N | K18: 1 | L18: N | M18: 1 | N18: N | O18: 1 | P18: N | Q18: =IF(ISNUMBER(U18),IF(U18>=9,"A",IF(U18>=7,"B",IF(U18>=5,"C+",IF(U18>=3,"C-","D")))),"N") -> D | S18: =G18/SUM(G$18:G$35)*G$36+I18/SUM(I$18:I$35)*I$36+K18/SUM(K$18:K$35)*K$36+M18/SUM(M$18:M$35)*M$36+O18/SUM(O$18:O$35)*O$36 -> 0.075778388 | T18: =S18 -> 0.075778388 | U18: =IF(EQ(SUM(G18*$G$36,I18*$I$36,K18*$K$36,M18*$M$36,O18*$O$36),0),"N",(IF(G18*$G$36>0,IF(ISNUMBER(H18),H18,0),0) + IF(I18*$I$36>0,IF(ISNUMBER(J18),J18,0),0) + IF(K18*$K$36>0,IF(ISNUMBER(L18),L18,0),0) + IF(M18*$M$36>0,IF(ISNUMBER(N18),N18,0),0) + IF(O18*$O$36>0,IF(ISNUMBER(P18),P18,0),0))/SUM(IF(G18*$G$36>0,1,0),IF(I18*$I$36>0,1,0),IF(K18*$K$36>0,1,0),IF(M18*$M$36>0,1,0),IF(O18*$O$36>0,1,0))) -> 0
A19: =Language!C31 -> Aspectos metodológicos
A20: =Language!C32 -> Definición de unos objetivos claros, concretos, realistas y adecuados | G20: 2 | H20: N | I20: 0 | J20: N | K20: 0 | L20: N | M20: 0 | N20: N | O20: 1 | P20: N | Q20: =IF(ISNUMBER(U20),IF(U20>=9,"A",IF(U20>=7,"B",IF(U20>=5,"C+",IF(U20>=3,"C-","D")))),"N") -> D | S20: =G20/SUM(G$18:G$35)*G$36+I20/SUM(I$18:I$35)*I$36+K20/SUM(K$18:K$35)*K$36+M20/SUM(M$18:M$35)*M$36+O20/SUM(O$18:O$35)*O$36 -> 0.035714286 | T20: =SUM(S20:S21) -> 0.071428571 | U20: =IF(EQ(SUM(G20*$G$36,I20*$I$36,K20*$K$36,M20*$M$36,O20*$O$36),0),"N",(IF(G20*$G$36>0,IF(ISNUMBER(H20),H20,0),0) + IF(I20*$I$36>0,IF(ISNUMBER(J20),J20,0),0) + IF(K20*$K$36>0,IF(ISNUMBER(L20),L20,0),0) + IF(M20*$M$36>0,IF(ISNUMBER(N20),N20,0),0) + IF(O20*$O$36>0,IF(ISNUMBER(P20),P20,0),0))/SUM(IF(G20*$G$36>0,1,0),IF(I20*$I$36>0,1,0),IF(K20*$K$36>0,1,0),IF(M20*$M$36>0,1,0),IF(O20*$O$36>0,1,0))) -> 0
A21: =Language!C33 -> Definición de la metodología, planificación temporal y de recursos | G21: 2 | H21: N | I21: 0 | J21: N | K21: 0 | L21: N | M21: 0 | N21: N | O21: 1 | P21: N | Q21: =IF(ISNUMBER(U21),IF(U21>=9,"A",IF(U21>=7,"B",IF(U21>=5,"C+",IF(U21>=3,"C-","D")))),"N") -> D | S21: =G21/SUM(G$18:G$35)*G$36+I21/SUM(I$18:I$35)*I$36+K21/SUM(K$18:K$35)*K$36+M21/SUM(M$18:M$35)*M$36+O21/SUM(O$18:O$35)*O$36 -> 0.035714286 | U21: =IF(EQ(SUM(G21*$G$36,I21*$I$36,K21*$K$36,M21*$M$36,O21*$O$36),0),"N",(IF(G21*$G$36>0,IF(ISNUMBER(H21),H21,0),0) + IF(I21*$I$36>0,IF(ISNUMBER(J21),J21,0),0) + IF(K21*$K$36>0,IF(ISNUMBER(L21),L21,0),0) + IF(M21*$M$36>0,IF(ISNUMBER(N21),N21,0),0) + IF(O21*$O$36>0,IF(ISNUMBER(P21),P21,0),0))/SUM(IF(G21*$G$36>0,1,0),IF(I21*$I$36>0,1,0),IF(K21*$K$36>0,1,0),IF(M21*$M$36>0,1,0),IF(O21*$O$36>0,1,0))) -> 0
A22: =Language!C34 -> Especificación y diseño
A23: =Language!C35 -> Estudio previo e identificación de los aspectos relevantes del problema y de su solución (e.g. estado del arte, estudio de mercado) | G23: 1 | H23: N | I23: 2 | J23: N | K23: 0 | L23: N | M23: 0 | N23: N | O23: 1 | P23: N | Q23: =IF(ISNUMBER(U23),IF(U23>=9,"A",IF(U23>=7,"B",IF(U23>=5,"C+",IF(U23>=3,"C-","D")))),"N") -> D | S23: =G23/SUM(G$18:G$35)*G$36+I23/SUM(I$18:I$35)*I$36+K23/SUM(K$18:K$35)*K$36+M23/SUM(M$18:M$35)*M$36+O23/SUM(O$18:O$35)*O$36 -> 0.056318681 | T23: =SUM(S23:S27) -> 0.33722527 | U23: =IF(EQ(SUM(G23*$G$36,I23*$I$36,K23*$K$36,M23*$M$36,O23*$O$36),0),"N",(IF(G23*$G$36>0,IF(ISNUMBER(H23),H23,0),0) + IF(I23*$I$36>0,IF(ISNUMBER(J23),J23,0),0) + IF(K23*$K$36>0,IF(ISNUMBER(L23),L23,0),0) + IF(M23*$M$36>0,IF(ISNUMBER(N23),N23,0),0) + IF(O23*$O$36>0,IF(ISNUMBER(P23),P23,0),0))/SUM(IF(G23*$G$36>0,1,0),IF(I23*$I$36>0,1,0),IF(K23*$K$36>0,1,0),IF(M23*$M$36>0,1,0),IF(O23*$O$36>0,1,0))) -> 0
A24: =Language!C36 -> Análisis de requerimientos | G24: 2 | H24: N | I24: 0 | J24: N | K24: 0 | L24: N | M24: 0 | N24: N | O24: 1 | P24: N | Q24: =IF(ISNUMBER(U24),IF(U24>=9,"A",IF(U24>=7,"B",IF(U24>=5,"C+",IF(U24>=3,"C-","D")))),"N") -> D | S24: =G24/SUM(G$18:G$35)*G$36+I24/SUM(I$18:I$35)*I$36+K24/SUM(K$18:K$35)*K$36+M24/SUM(M$18:M$35)*M$36+O24/SUM(O$18:O$35)*O$36 -> 0.035714286 | U24: =IF(EQ(SUM(G24*$G$36,I24*$I$36,K24*$K$36,M24*$M$36,O24*$O$36),0),"N",(IF(G24*$G$36>0,IF(ISNUMBER(H24),H24,0),0) + IF(I24*$I$36>0,IF(ISNUMBER(J24),J24,0),0) + IF(K24*$K$36>0,IF(ISNUMBER(L24),L24,0),0) + IF(M24*$M$36>0,IF(ISNUMBER(N24),N24,0),0) + IF(O24*$O$36>0,IF(ISNUMBER(P24),P24,0),0))/SUM(IF(G24*$G$36>0,1,0),IF(I24*$I$36>0,1,0),IF(K24*$K$36>0,1,0),IF(M24*$M$36>0,1,0),IF(O24*$O$36>0,1,0))) -> 0
A25: =Language!C37 -> Diseño adecuado de la propuesta | G25: 1 | H25: N | I25: 2 | J25: N | K25: 2 | L25: N | M25: 2 | N25: N | O25: 1 | P25: N | Q25: =IF(ISNUMBER(U25),IF(U25>=9,"A",IF(U25>=7,"B",IF(U25>=5,"C+",IF(U25>=3,"C-","D")))),"N") -> D | S25: =G25/SUM(G$18:G$35)*G$36+I25/SUM(I$18:I$35)*I$36+K25/SUM(K$18:K$35)*K$36+M25/SUM(M$18:M$35)*M$36+O25/SUM(O$18:O$35)*O$36 -> 0.13369963 | U25: =IF(EQ(SUM(G25*$G$36,I25*$I$36,K25*$K$36,M25*$M$36,O25*$O$36),0),"N",(IF(G25*$G$36>0,IF(ISNUMBER(H25),H25,0),0) + IF(I25*$I$36>0,IF(ISNUMBER(J25),J25,0),0) + IF(K25*$K$36>0,IF(ISNUMBER(L25),L25,0),0) + IF(M25*$M$36>0,IF(ISNUMBER(N25),N25,0),0) + IF(O25*$O$36>0,IF(ISNUMBER(P25),P25,0),0))/SUM(IF(G25*$G$36>0,1,0),IF(I25*$I$36>0,1,0),IF(K25*$K$36>0,1,0),IF(M25*$M$36>0,1,0),IF(O25*$O$36>0,1,0))) -> 0
A26: =Language!C38 -> Elección de herramientas, tecnologías y fuentes de información adecuadas para el desarrollo del trabajo | G26: 1 | H26: N | I26: 1 | J26: N | K26: 1 | L26: N | M26: 1 | N26: N | O26: 1 | P26: N | Q26: =IF(ISNUMBER(U26),IF(U26>=9,"A",IF(U26>=7,"B",IF(U26>=5,"C+",IF(U26>=3,"C-","D")))),"N") -> D | S26: =G26/SUM(G$18:G$35)*G$36+I26/SUM(I$18:I$35)*I$36+K26/SUM(K$18:K$35)*K$36+M26/SUM(M$18:M$35)*M$36+O26/SUM(O$18:O$35)*O$36 -> 0.075778388 | U26: =IF(EQ(SUM(G26*$G$36,I26*$I$36,K26*$K$36,M26*$M$36,O26*$O$36),0),"N",(IF(G26*$G$36>0,IF(ISNUMBER(H26),H26,0),0) + IF(I26*$I$36>0,IF(ISNUMBER(J26),J26,0),0) + IF(K26*$K$36>0,IF(ISNUMBER(L26),L26,0),0) + IF(M26*$M$36>0,IF(ISNUMBER(N26),N26,0),0) + IF(O26*$O$36>0,IF(ISNUMBER(P26),P26,0),0))/SUM(IF(G26*$G$36>0,1,0),IF(I26*$I$36>0,1,0),IF(K26*$K$36>0,1,0),IF(M26*$M$36>0,1,0),IF(O26*$O$36>0,1,0))) -> 0
A27: =Language!C39 -> Grado de análisis y tratamiento del impacto ético-social, de sostenibilidad y de diversidad del trabajo | G27: 1 | H27: N | I27: 0 | J27: N | K27: 0 | L27: N | M27: 1 | N27: N | O27: 1 | P27: N | Q27: =IF(ISNUMBER(U27),IF(U27>=9,"A",IF(U27>=7,"B",IF(U27>=5,"C+",IF(U27>=3,"C-","D")))),"N") -> D | S27: =G27/SUM(G$18:G$35)*G$36+I27/SUM(I$18:I$35)*I$36+K27/SUM(K$18:K$35)*K$36+M27/SUM(M$18:M$35)*M$36+O27/SUM(O$18:O$35)*O$36 -> 0.035714286 | U27: =IF(EQ(SUM(G27*$G$36,I27*$I$36,K27*$K$36,M27*$M$36,O27*$O$36),0),"N",(IF(G27*$G$36>0,IF(ISNUMBER(H27),H27,0),0) + IF(I27*$I$36>0,IF(ISNUMBER(J27),J27,0),0) + IF(K27*$K$36>0,IF(ISNUMBER(L27),L27,0),0) + IF(M27*$M$36>0,IF(ISNUMBER(N27),N27,0),0) + IF(O27*$O$36>0,IF(ISNUMBER(P27),P27,0),0))/SUM(IF(G27*$G$36>0,1,0),IF(I27*$I$36>0,1,0),IF(K27*$K$36>0,1,0),IF(M27*$M$36>0,1,0),IF(O27*$O$36>0,1,0))) -> 0
A28: =Language!C40 -> Ejecución e implementación del proyecto
A29: =Language!C41 -> Seguimiento de la planificación y capacidad de adaptación | G29: 0 | H29: N | I29: 1 | J29: N | K29: 1 | L29: N | M29: 1 | N29: N | O29: 1 | P29: N | Q29: =IF(ISNUMBER(U29),IF(U29>=9,"A",IF(U29>=7,"B",IF(U29>=5,"C+",IF(U29>=3,"C-","D")))),"N") -> D | S29: =G29/SUM(G$18:G$35)*G$36+I29/SUM(I$18:I$35)*I$36+K29/SUM(K$18:K$35)*K$36+M29/SUM(M$18:M$35)*M$36+O29/SUM(O$18:O$35)*O$36 -> 0.057921245 | T29: =SUM(S29:S32) -> 0.2882326 | U29: =IF(EQ(SUM(G29*$G$36,I29*$I$36,K29*$K$36,M29*$M$36,O29*$O$36),0),"N",(IF(G29*$G$36>0,IF(ISNUMBER(H29),H29,0),0) + IF(I29*$I$36>0,IF(ISNUMBER(J29),J29,0),0) + IF(K29*$K$36>0,IF(ISNUMBER(L29),L29,0),0) + IF(M29*$M$36>0,IF(ISNUMBER(N29),N29,0),0) + IF(O29*$O$36>0,IF(ISNUMBER(P29),P29,0),0))/SUM(IF(G29*$G$36>0,1,0),IF(I29*$I$36>0,1,0),IF(K29*$K$36>0,1,0),IF(M29*$M$36>0,1,0),IF(O29*$O$36>0,1,0))) -> 0
A30: =Language!C42 -> Calidad de la contribución técnica y/o científica del proyecto. Calidad de la solución/producto en desarrollo/obtenido | G30: 0 | H30: N | I30: 2 | J30: N | K30: 2 | L30: N | M30: 2 | N30: N | O30: 1 | P30: N | Q30: =IF(ISNUMBER(U30),IF(U30>=9,"A",IF(U30>=7,"B",IF(U30>=5,"C+",IF(U30>=3,"C-","D")))),"N") -> D | S30: =G30/SUM(G$18:G$35)*G$36+I30/SUM(I$18:I$35)*I$36+K30/SUM(K$18:K$35)*K$36+M30/SUM(M$18:M$35)*M$36+O30/SUM(O$18:O$35)*O$36 -> 0.11584249 | U30: =IF(EQ(SUM(G30*$G$36,I30*$I$36,K30*$K$36,M30*$M$36,O30*$O$36),0),"N",(IF(G30*$G$36>0,IF(ISNUMBER(H30),H30,0),0) + IF(I30*$I$36>0,IF(ISNUMBER(J30),J30,0),0) + IF(K30*$K$36>0,IF(ISNUMBER(L30),L30,0),0) + IF(M30*$M$36>0,IF(ISNUMBER(N30),N30,0),0) + IF(O30*$O$36>0,IF(ISNUMBER(P30),P30,0),0))/SUM(IF(G30*$G$36>0,1,0),IF(I30*$I$36>0,1,0),IF(K30*$K$36>0,1,0),IF(M30*$M$36>0,1,0),IF(O30*$O$36>0,1,0))) -> 0
A31: =Language!C43 -> Grado de innovación de la solución presentada | G31: 0 | H31: N | I31: 1 | J31: N | K31: 1 | L31: N | M31: 1 | N31: N | O31: 1 | P31: N | Q31: =IF(ISNUMBER(U31),IF(U31>=9,"A",IF(U31>=7,"B",IF(U31>=5,"C+",IF(U31>=3,"C-","D")))),"N") -> D | S31: =G31/SUM(G$18:G$35)*G$36+I31/SUM(I$18:I$35)*I$36+K31/SUM(K$18:K$35)*K$36+M31/SUM(M$18:M$35)*M$36+O31/SUM(O$18:O$35)*O$36 -> 0.057921245 | U31: =IF(EQ(SUM(G31*$G$36,I31*$I$36,K31*$K$36,M31*$M$36,O31*$O$36),0),"N",(IF(G31*$G$36>0,IF(ISNUMBER(H31),H31,0),0) + IF(I31*$I$36>0,IF(ISNUMBER(J31),J31,0),0) + IF(K31*$K$36>0,IF(ISNUMBER(L31),L31,0),0) + IF(M31*$M$36>0,IF(ISNUMBER(#REF!),#REF!,0),0) + IF(O31*$O$36>0,IF(ISNUMBER(P31),P31,0),0))/SUM(IF(G31*$G$36>0,1,0),IF(I31*$I$36>0,1,0),IF(K31*$K$36>0,1,0),IF(M31*$M$36>0,1,0),IF(O31*$O$36>0,1,0))) -> 0
A32: =Language!C44 -> Conclusiones y discusión de los resultados | G32: 0 | H32: N | I32: 0 | J32: N | K32: 1 | L32: N | M32: 2 | N32: N | O32: 1 | P32: N | Q32: =IF(ISNUMBER(U32),IF(U32>=9,"A",IF(U32>=7,"B",IF(U32>=5,"C+",IF(U32>=3,"C-","D")))),"N") -> D | S32: =G32/SUM(G$18:G$35)*G$36+I32/SUM(I$18:I$35)*I$36+K32/SUM(K$18:K$35)*K$36+M32/SUM(M$18:M$35)*M$36+O32/SUM(O$18:O$35)*O$36 -> 0.056547619 | U32: =IF(EQ(SUM(G32*$G$36,I32*$I$36,K32*$K$36,M32*$M$36,O32*$O$36),0),"N",(IF(G32*$G$36>0,IF(ISNUMBER(H32),H32,0),0) + IF(I32*$I$36>0,IF(ISNUMBER(J32),J32,0),0) + IF(K32*$K$36>0,IF(ISNUMBER(L32),L32,0),0) + IF(M32*$M$36>0,IF(ISNUMBER(N31),N31,0),0) + IF(O32*$O$36>0,IF(ISNUMBER(P32),P32,0),0))/SUM(IF(G32*$G$36>0,1,0),IF(I32*$I$36>0,1,0),IF(K32*$K$36>0,1,0),IF(M32*$M$36>0,1,0),IF(O32*$O$36>0,1,0))) -> 0
A33: =Language!C45 -> Aspectos formales de la memoria
A34: =Language!C46 -> Redacción adecuada, utilización flexible de un lenguaje inclusivo, y organización clara y correcta del contenido | G34: 2 | H34: N | I34: 2 | J34: N | K34: 2 | L34: N | M34: 2 | N34: N | O34: 1 | P34: N | Q34: =IF(ISNUMBER(U34),IF(U34>=9,"A",IF(U34>=7,"B",IF(U34>=5,"C+",IF(U34>=3,"C-","D")))),"N") -> D | S34: =G34/SUM(G$18:G$35)*G$36+I34/SUM(I$18:I$35)*I$36+K34/SUM(K$18:K$35)*K$36+M34/SUM(M$18:M$35)*M$36+O34/SUM(O$18:O$35)*O$36 -> 0.15155678 | T34: =SUM(S34:S35) -> 0.22733516 | U34: =IF(EQ(SUM(G34*$G$36,I34*$I$36,K34*$K$36,M34*$M$36,O34*$O$36),0),"N",(IF(G34*$G$36>0,IF(ISNUMBER(H34),H34,0),0) + IF(I34*$I$36>0,IF(ISNUMBER(J34),J34,0),0) + IF(K34*$K$36>0,IF(ISNUMBER(L34),L34,0),0) + IF(M34*$M$36>0,IF(ISNUMBER(N34),N34,0),0) + IF(O34*$O$36>0,IF(ISNUMBER(P34),P34,0),0))/SUM(IF(G34*$G$36>0,1,0),IF(I34*$I$36>0,1,0),IF(K34*$K$36>0,1,0),IF(M34*$M$36>0,1,0),IF(O34*$O$36>0,1,0))) -> 0
A35: =Language!C47 -> Fuentes de información y referencias bibliográficas | G35: 1 | H35: N | I35: 1 | J35: N | K35: 1 | L35: N | M35: 1 | N35: N | O35: 1 | P35: N | Q35: =IF(ISNUMBER(U35),IF(U35>=9,"A",IF(U35>=7,"B",IF(U35>=5,"C+",IF(U35>=3,"C-","D")))),"N") -> D | S35: =G35/SUM(G$18:G$35)*G$36+I35/SUM(I$18:I$35)*I$36+K35/SUM(K$18:K$35)*K$36+M35/SUM(M$18:M$35)*M$36+O35/SUM(O$18:O$35)*O$36 -> 0.075778388 | U35: =IF(EQ(SUM(G35*$G$36,I35*$I$36,K35*$K$36,M35*$M$36,O35*$O$36),0),"N",(IF(G35*$G$36>0,IF(ISNUMBER(H35),H35,0),0) + IF(I35*$I$36>0,IF(ISNUMBER(J35),J35,0),0) + IF(K35*$K$36>0,IF(ISNUMBER(L35),L35,0),0) + IF(M35*$M$36>0,IF(ISNUMBER(N35),N35,0),0) + IF(O35*$O$36>0,IF(ISNUMBER(P35),P35,0),0))/SUM(IF(G35*$G$36>0,1,0),IF(I35*$I$36>0,1,0),IF(K35*$K$36>0,1,0),IF(M35*$M$36>0,1,0),IF(O35*$O$36>0,1,0))) -> 0
A36: =Language!C51 -> % PEC en nota final del tutor | G36: 0.25 | I36: 0.25 | K36: 0.25 | M36: 0.25 | O36: 0 | Q36: =G36+I36+K36+M36+O36 -> 1 | S36: =SUM(S18:S35) -> 1
A37: =Language!C27 -> Final | G37: =ROUND(SUMPRODUCT(G18:G35,H18:H35)/SUM(G18:G35),1) -> 0 | I37: =ROUND(SUMPRODUCT(I18:I35,J18:J35)/SUM(I18:I35),1) -> 0 | K37: =ROUND(SUMPRODUCT(K18:K35,L18:L35)/SUM(K18:K35),1) -> 0 | M37: =ROUND(SUMPRODUCT(M18:M35,N18:N35)/SUM(M18:M35),1) -> 0 | O37: =ROUND(SUMPRODUCT(O18:O35,P18:P35)/SUM(O18:O35),1) -> 0 | Q37: =ROUND(IF(ISNUMBER(G37),G37,0)*G36+IF(ISNUMBER(I37),I37,0)*I36+IF(ISNUMBER(K37),K37,0)*K36+IF(ISNUMBER(M37),M37,0)*M36+IF(ISNUMBER(O37),O37,0)*O36,1) -> 0
G38: =IF(G37>=9,"A",IF(G37>=7,"B",IF(G37>=5,"C+",IF(G37>=3,"C-","D")))) -> D | I38: =IF(I37>=9,"A",IF(I37>=7,"B",IF(I37>=5,"C+",IF(I37>=3,"C-","D")))) -> D | K38: =IF(K37>=9,"A",IF(K37>=7,"B",IF(K37>=5,"C+",IF(K37>=3,"C-","D")))) -> D | M38: =IF(M37>=9,"A",IF(M37>=7,"B",IF(M37>=5,"C+",IF(M37>=3,"C-","D")))) -> D | O38: =IF(O37>=9,"A",IF(O37>=7,"B",IF(O37>=5,"C+",IF(O37>=3,"C-","D")))) -> D | Q38: =IF(Q37>=9,"A",IF(Q37>=7,"B",IF(Q37>=5,"C+",IF(Q37>=3,"C-","D")))) -> D
A40: =Language!C54 -> PEC1. Observaciones y recomendaciones:
A42: =Language!C55 -> PEC2. Observaciones y recomendaciones:
A44: =Language!C56 -> PEC3. Observaciones y recomendaciones:
A46: =Language!C57 -> PEC4. Observaciones y recomendaciones:
A48: =Language!C58 -> PEC5. Observaciones y recomendaciones:

Sheet RubricExaminer1
D1: =RubricTutor!D1 -> Bachelor's degree in Techniques for Software Application Development
D2: =RubricTutor!D2 -> Trabajo final - Semestre 2025-1
A4: =Language!C5 -> Nombre del/de la estudiante: | D4: =RubricTutor!D4
A5: =Language!C6 -> Título del trabajo: | D5: =RubricTutor!D5
A6: =Language!C7 -> Programa: | D6: =RubricTutor!D6 -> Bachelor's degree in Techniques for Software Application Development
A7: =Language!C9 -> Tutor/a: | D7: =RubricTutor!D8
A8: =Language!C8 -> Semestre: | D8: =RubricTutor!D7 -> 2025-1
A9: =Language!C10 -> Evaluador/a 1: | D9: =RubricTutor!D9
A11: A | C11: B | E11: C+ | G11: C- | I11: D
A12: 10 | B12: 9 | C12: 8 | D12: 7 | E12: 6 | F12: 5 | G12: 4 | H12: 3 | I12: 2 | J12: 1 | K12: 0
A14: =Language!C60 -> Evaluación del Evaluador/a 1 | G14: =Language!C63 -> Entrega final y defensa
A15: =Language!C31 -> Aspectos metodológicos
A16: =Language!C32 -> Definición de unos objetivos claros, concretos, realistas y adecuados | G16: N
A17: =Language!C33 -> Definición de la metodología, planificación temporal y de recursos | G17: N
A18: =Language!C34 -> Especificación y diseño
A19: =Language!C35 -> Estudio previo e identificación de los aspectos relevantes del problema y de su solución (e.g. estado del arte, estudio de mercado) | G19: N
A20: =Language!C36 -> Análisis de requerimientos | G20: N
A21: =Language!C37 -> Diseño adecuado de la propuesta | G21: N
A22: =Language!C38 -> Elección de herramientas, tecnologías y fuentes de información adecuadas para el desarrollo del trabajo | G22: N
A23: =Language!C39 -> Grado de análisis y tratamiento del impacto ético-social, de sostenibilidad y de diversidad del trabajo | G23: N
A24: =Language!C40 -> Ejecución e implementación del proyecto
A25: =Language!C42 -> Calidad de la contribución técnica y/o científica del proyecto. Calidad de la solución/producto en desarrollo/obtenido | G25: N
A26: =Language!C43 -> Grado de innovación de la solución presentada | G26: N
A27: =Language!C44 -> Conclusiones y discusión de los resultados | G27: N
A28: =Language!C45 -> Aspectos formales de la memoria
A29: =Language!C46 -> Redacción adecuada, utilización flexible de un lenguaje inclusivo, y organización clara y correcta del contenido | G29: N
A30: =Language!C47 -> Fuentes de información y referencias bibliográficas | G30: N
A31: =Language!C48 -> Defensa del proyecto
A32: =Language!C49 -> Calidad de la presentación oral y de los recursos visuales | G32: N
A33: =Language!C50 -> Respuesta clara y fundamentada a las preguntas de la comisión | G33: N
A34: =Language!C27 -> Final | G34: =ROUND(SUMPRODUCT(G16:G33,DefenseSummary!B9:B26)/SUM(DefenseSummary!B9:B26),1) -> 0
G35: =IF(G34>=9,"A",IF(G34>=7,"B",IF(G34>=5,"C+",IF(G34>=3,"C-","D")))) -> D
A37: =Language!C64 -> Marca esta casilla si crees que este trabajo merece ser considerado para matrícula de honor | G37: FALSE
A39: =Language!C59 -> Observaciones y recomendaciones:

Sheet RubricExaminer2
D1: =RubricTutor!D1 -> Bachelor's degree in Techniques for Software Application Development
D2: =RubricTutor!D2 -> Trabajo final - Semestre 2025-1
A4: =Language!C5 -> Nombre del/de la estudiante: | D4: =RubricTutor!D4
A5: =Language!C6 -> Título del trabajo: | D5: =RubricTutor!D5
A6: =Language!C7 -> Programa: | D6: =RubricTutor!D6 -> Bachelor's degree in Techniques for Software Application Development
A7: =Language!C9 -> Tutor/a: | D7: =RubricTutor!D8
A8: =Language!C8 -> Semestre: | D8: =RubricTutor!D7 -> 2025-1
A9: =Language!C11 -> Evaluador/a 2: | D9: =RubricTutor!D10
A11: A | C11: B | E11: C+ | G11: C- | I11: D
A12: 10 | B12: 9 | C12: 8 | D12: 7 | E12: 6 | F12: 5 | G12: 4 | H12: 3 | I12: 2 | J12: 1 | K12: 0
A14: =Language!C61 -> Evaluación del Evaluador/a 2 | G14: =Language!C63 -> Entrega final y defensa
A15: =Language!C31 -> Aspectos metodológicos
A16: =Language!C32 -> Definición de unos objetivos claros, concretos, realistas y adecuados | G16: N
A17: =Language!C33 -> Definición de la metodología, planificación temporal y de recursos | G17: N
A18: =Language!C34 -> Especificación y diseño
A19: =Language!C35 -> Estudio previo e identificación de los aspectos relevantes del problema y de su solución (e.g. estado del arte, estudio de mercado) | G19: N
A20: =Language!C36 -> Análisis de requerimientos | G20: N
A21: =Language!C37 -> Diseño adecuado de la propuesta | G21: N
A22: =Language!C38 -> Elección de herramientas, tecnologías y fuentes de información adecuadas para el desarrollo del trabajo | G22: N
A23: =Language!C39 -> Grado de análisis y tratamiento del impacto ético-social, de sostenibilidad y de diversidad del trabajo | G23: N
A24: =Language!C40 -> Ejecución e implementación del proyecto
A25: =Language!C42 -> Calidad de la contribución técnica y/o científica del proyecto. Calidad de la solución/producto en desarrollo/obtenido | G25: N
A26: =Language!C43 -> Grado de innovación de la solución presentada | G26: N
A27: =Language!C44 -> Conclusiones y discusión de los resultados | G27: N
A28: =Language!C45 -> Aspectos formales de la memoria
A29: =Language!C46 -> Redacción adecuada, utilización flexible de un lenguaje inclusivo, y organización clara y correcta del contenido | G29: N
A30: =Language!C47 -> Fuentes de información y referencias bibliográficas | G30: N
A31: =Language!C48 -> Defensa del proyecto
A32: =Language!C49 -> Calidad de la presentación oral y de los recursos visuales | G32: N
A33: =Language!C50 -> Respuesta clara y fundamentada a las preguntas de la comisión | G33: N
A34: =Language!C27 -> Final | G34: =ROUND(SUMPRODUCT(G16:G33,DefenseSummary!B9:B26)/SUM(DefenseSummary!B9:B26),1) -> 0
G35: =IF(G34>=9,"A",IF(G34>=7,"B",IF(G34>=5,"C+",IF(G34>=3,"C-","D")))) -> D
A37: =Language!C64 -> Marca esta casilla si crees que este trabajo merece ser considerado para matrícula de honor | G37: FALSE
A39: =Language!C59 -> Observaciones y recomendaciones:

Sheet RubricExaminer3
D1: =RubricTutor!D1 -> Bachelor's degree in Techniques for Software Application Development
D2: =RubricTutor!D2 -> Trabajo final - Semestre 2025-1
A4: =Language!C5 -> Nombre del/de la estudiante: | D4: =RubricTutor!D4
A5: =Language!C6 -> Título del trabajo: | D5: =RubricTutor!D5
A6: =Language!C7 -> Programa: | D6: =RubricTutor!D6 -> Bachelor's degree in Techniques for Software Application Development
A7: =Language!C9 -> Tutor/a: | D7: =RubricTutor!D8
A8: =Language!C8 -> Semestre: | D8: =RubricTutor!D7 -> 2025-1
A9: =Language!C12 -> Evaluador/a 3: | D9: =RubricTutor!D11
A11: A | C11: B | E11: C+ | G11: C- | I11: D
A12: 10 | B12: 9 | C12: 8 | D12: 7 | E12: 6 | F12: 5 | G12: 4 | H12: 3 | I12: 2 | J12: 1 | K12: 0
A14: =Language!C62 -> Evaluación del Evaluador/a 3 | G14: =Language!C63 -> Entrega final y defensa
A15: =Language!C31 -> Aspectos metodológicos
A16: =Language!C32 -> Definición de unos objetivos claros, concretos, realistas y adecuados | G16: N
A17: =Language!C33 -> Definición de la metodología, planificación temporal y de recursos | G17: N
A18: =Language!C34 -> Especificación y diseño
A19: =Language!C35 -> Estudio previo e identificación de los aspectos relevantes del problema y de su solución (e.g. estado del arte, estudio de mercado) | G19: N
A20: =Language!C36 -> Análisis de requerimientos | G20: N
A21: =Language!C37 -> Diseño adecuado de la propuesta | G21: N
A22: =Language!C38 -> Elección de herramientas, tecnologías y fuentes de información adecuadas para el desarrollo del trabajo | G22: N
A23: =Language!C39 -> Grado de análisis y tratamiento del impacto ético-social, de sostenibilidad y de diversidad del trabajo | G23: N
A24: =Language!C40 -> Ejecución e implementación del proyecto
A25: =Language!C42 -> Calidad de la contribución técnica y/o científica del proyecto. Calidad de la solución/producto en desarrollo/obtenido | G25: N
A26: =Language!C43 -> Grado de innovación de la solución presentada | G26: N
A27: =Language!C44 -> Conclusiones y discusión de los resultados | G27: N
A28: =Language!C45 -> Aspectos formales de la memoria
A29: =Language!C46 -> Redacción adecuada, utilización flexible de un lenguaje inclusivo, y organización clara y correcta del contenido | G29: N
A30: =Language!C47 -> Fuentes de información y referencias bibliográficas | G30: N
A31: =Language!C48 -> Defensa del proyecto
A32: =Language!C49 -> Calidad de la presentación oral y de los recursos visuales | G32: N
A33: =Language!C50 -> Respuesta clara y fundamentada a las preguntas de la comisión | G33: N
A34: =Language!C27 -> Final | G34: =ROUND(SUMPRODUCT(G16:G33,DefenseSummary!B9:B26)/SUM(DefenseSummary!B9:B26),1) -> 0
G35: =IF(G34>=9,"A",IF(G34>=7,"B",IF(G34>=5,"C+",IF(G34>=3,"C-","D")))) -> D
A37: =Language!C64 -> Marca esta casilla si crees que este trabajo merece ser considerado para matrícula de honor | G37: FALSE
A39: =Language!C59 -> Observaciones y recomendaciones:

Sheet DefenseSummary
A1: =Language!C5 -> Nombre del/de la estudiante: | B1: =RubricTutor!D4
A2: =Language!C6 -> Título del trabajo: | B2: =RubricTutor!D5
A3: =Language!C9 -> Tutor/a: | B3: =RubricTutor!D8
C5: =Language!C10 -> Evaluador/a 1: | D5: =Language!C11 -> Evaluador/a 2: | E5: =Language!C12 -> Evaluador/a 3:
A6: =Language!C66 -> Nombre evaluadores/as: | C6: =RubricTutor!D9 | D6: =RubricTutor!D10 | E6: =RubricTutor!D11
A7: =Language!C67 -> Participación evaluador/a (0: no participa; 1: participa) | C7: 1 | D7: 1 | E7: 1
A8: =Language!C31 -> Aspectos metodológicos | B8: =Language!C25 -> Peso | C8: =Language!C26 -> Nota | D8: =Language!C26 -> Nota | E8: =Language!C26 -> Nota | F8: =Language!C28 -> Nota media
A9: =Language!C32 -> Definición de unos objetivos claros, concretos, realistas y adecuados | B9: 1 | C9: =RubricExaminer1!G16 -> N | D9: =RubricExaminer2!G16 -> N | E9: =RubricExaminer3!G16 -> N | F9: =ROUND(SUMPRODUCT(C$7:E$7,C9:E9)/SUM(C$7:E$7),1) -> 0 | G9: =IF(ISNUMBER(F9),IF(F9>=9,"A",IF(F9>=7,"B",IF(F9>=5,"C+",IF(F9>=3,"C-","D")))),"N") -> D
A10: =Language!C33 -> Definición de la metodología, planificación temporal y de recursos | B10: 1 | C10: =RubricExaminer1!G17 -> N | D10: =RubricExaminer2!G17 -> N | E10: =RubricExaminer3!G17 -> N | F10: =ROUND(SUMPRODUCT(C$7:E$7,C10:E10)/SUM(C$7:E$7),1) -> 0 | G10: =IF(ISNUMBER(F10),IF(F10>=9,"A",IF(F10>=7,"B",IF(F10>=5,"C+",IF(F10>=3,"C-","D")))),"N") -> D
A11: =Language!C34 -> Especificación y diseño
A12: =Language!C35 -> Estudio previo e identificación de los aspectos relevantes del problema y de su solución (e.g. estado del arte, estudio de mercado) | B12: 1 | C12: =RubricExaminer1!G19 -> N | D12: =RubricExaminer2!G19 -> N | E12: =RubricExaminer3!G19 -> N | F12: =ROUND(SUMPRODUCT(C$7:E$7,C12:E12)/SUM(C$7:E$7),1) -> 0 | G12: =IF(ISNUMBER(F12),IF(F12>=9,"A",IF(F12>=7,"B",IF(F12>=5,"C+",IF(F12>=3,"C-","D")))),"N") -> D
A13: =Language!C36 -> Análisis de requerimientos | B13: 1 | C13: =RubricExaminer1!G20 -> N | D13: =RubricExaminer2!G20 -> N | E13: =RubricExaminer3!G20 -> N | F13: =ROUND(SUMPRODUCT(C$7:E$7,C13:E13)/SUM(C$7:E$7),1) -> 0 | G13: =IF(ISNUMBER(F13),IF(F13>=9,"A",IF(F13>=7,"B",IF(F13>=5,"C+",IF(F13>=3,"C-","D")))),"N") -> D
A14: =Language!C37 -> Diseño adecuado de la propuesta | B14: 2 | C14: =RubricExaminer1!G21 -> N | D14: =RubricExaminer2!G21 -> N | E14: =RubricExaminer3!G21 -> N | F14: =ROUND(SUMPRODUCT(C$7:E$7,C14:E14)/SUM(C$7:E$7),1) -> 0 | G14: =IF(ISNUMBER(F14),IF(F14>=9,"A",IF(F14>=7,"B",IF(F14>=5,"C+",IF(F14>=3,"C-","D")))),"N") -> D
A15: =Language!C38 -> Elección de herramientas, tecnologías y fuentes de información adecuadas para el desarrollo del trabajo | B15: 1 | C15: =RubricExaminer1!G22 -> N | D15: =RubricExaminer2!G22 -> N | E15: =RubricExaminer3!G22 -> N | F15: =ROUND(SUMPRODUCT(C$7:E$7,C15:E15)/SUM(C$7:E$7),1) -> 0 | G15: =IF(ISNUMBER(F15),IF(F15>=9,"A",IF(F15>=7,"B",IF(F15>=5,"C+",IF(F15>=3,"C-","D")))),"N") -> D
A16: =Language!C39 -> Grado de análisis y tratamiento del impacto ético-social, de sostenibilidad y de diversidad del trabajo | B16: 1 | C16: =RubricExaminer1!G23 -> N | D16: =RubricExaminer2!G23 -> N | E16: =RubricExaminer3!G23 -> N | F16: =ROUND(SUMPRODUCT(C$7:E$7,C16:E16)/SUM(C$7:E$7),1) -> 0 | G16: =IF(ISNUMBER(F16),IF(F16>=9,"A",IF(F16>=7,"B",IF(F16>=5,"C+",IF(F16>=3,"C-","D")))),"N") -> D
A17: =Language!C40 -> Ejecución e implementación del proyecto
A18: =Language!C42 -> Calidad de la contribución técnica y/o científica del proyecto. Calidad de la solución/producto en desarrollo/obtenido | B18: 3 | C18: =RubricExaminer1!G25 -> N | D18: =RubricExaminer2!G25 -> N | E18: =RubricExaminer3!G25 -> N | F18: =ROUND(SUMPRODUCT(C$7:E$7,C18:E18)/SUM(C$7:E$7),1) -> 0 | G18: =IF(ISNUMBER(F18),IF(F18>=9,"A",IF(F18>=7,"B",IF(F18>=5,"C+",IF(F18>=3,"C-","D")))),"N") -> D
A19: =Language!C43 -> Grado de innovación de la solución presentada | B19: 1 | C19: =RubricExaminer1!G26 -> N | D19: =RubricExaminer2!G26 -> N | E19: =RubricExaminer3!G26 -> N | F19: =ROUND(SUMPRODUCT(C$7:E$7,C19:E19)/SUM(C$7:E$7),1) -> 0 | G19: =IF(ISNUMBER(F19),IF(F19>=9,"A",IF(F19>=7,"B",IF(F19>=5,"C+",IF(F19>=3,"C-","D")))),"N") -> D
A20: =Language!C44 -> Conclusiones y discusión de los resultados | B20: 2 | C20: =RubricExaminer1!G27 -> N | D20: =RubricExaminer2!G27 -> N | E20: =RubricExaminer3!G27 -> N | F20: =ROUND(SUMPRODUCT(C$7:E$7,C20:E20)/SUM(C$7:E$7),1) -> 0 | G20: =IF(ISNUMBER(F20),IF(F20>=9,"A",IF(F20>=7,"B",IF(F20>=5,"C+",IF(F20>=3,"C-","D")))),"N") -> D
A21: =Language!C45 -> Aspectos formales de la memoria
A22: =Language!C46 -> Redacción adecuada, utilización flexible de un lenguaje inclusivo, y organización clara y correcta del contenido | B22: 2 | C22: =RubricExaminer1!G29 -> N | D22: =RubricExaminer2!G29 -> N | E22: =RubricExaminer3!G29 -> N | F22: =ROUND(SUMPRODUCT(C$7:E$7,C22:E22)/SUM(C$7:E$7),1) -> 0 | G22: =IF(ISNUMBER(F22),IF(F22>=9,"A",IF(F22>=7,"B",IF(F22>=5,"C+",IF(F22>=3,"C-","D")))),"N") -> D
A23: =Language!C47 -> Fuentes de información y referencias bibliográficas | B23: 1 | C23: =RubricExaminer1!G30 -> N | D23: =RubricExaminer2!G30 -> N | E23: =RubricExaminer3!G30 -> N | F23: =ROUND(SUMPRODUCT(C$7:E$7,C23:E23)/SUM(C$7:E$7),1) -> 0 | G23: =IF(ISNUMBER(F23),IF(F23>=9,"A",IF(F23>=7,"B",IF(F23>=5,"C+",IF(F23>=3,"C-","D")))),"N") -> D
A24: =Language!C48 -> Defensa del proyecto
A25: =Language!C49 -> Calidad de la presentación oral y de los recursos visuales | B25: 1 | C25: =RubricExaminer1!G32 -> N | D25: =RubricExaminer2!G32 -> N | E25: =RubricExaminer3!G32 -> N | F25: =ROUND(SUMPRODUCT(C$7:E$7,C25:E25)/SUM(C$7:E$7),1) -> 0 | G25: =IF(ISNUMBER(F25),IF(F25>=9,"A",IF(F25>=7,"B",IF(F25>=5,"C+",IF(F25>=3,"C-","D")))),"N") -> D
A26: =Language!C50 -> Respuesta clara y fundamentada a las preguntas de la comisión | B26: 1 | C26: =RubricExaminer1!G33 -> N | D26: =RubricExaminer2!G33 -> N | E26: =RubricExaminer3!G33 -> N | F26: =ROUND(SUMPRODUCT(C$7:E$7,C26:E26)/SUM(C$7:E$7),1) -> 0 | G26: =IF(ISNUMBER(F26),IF(F26>=9,"A",IF(F26>=7,"B",IF(F26>=5,"C+",IF(F26>=3,"C-","D")))),"N") -> D
A27: =Language!C27 -> Final | C27: =ROUND(SUMPRODUCT($B9:$B26,C9:C26)/SUM($B9:$B26),1) -> 0 | D27: =ROUND(SUMPRODUCT($B9:$B26,D9:D26)/SUM($B9:$B26),1) -> 0 | E27: =ROUND(SUMPRODUCT($B9:$B26,E9:E26)/SUM($B9:$B26),1) -> 0 | F27: =ROUND(SUMPRODUCT($B9:$B26,F9:F26)/SUM($B9:$B26),1) -> 0
C28: =IF(C27>=9,"A",IF(C27>=7,"B",IF(C27>=5,"C+",IF(C27>=3,"C-","D")))) -> D | D28: =IF(D27>=9,"A",IF(D27>=7,"B",IF(D27>=5,"C+",IF(D27>=3,"C-","D")))) -> D | E28: =IF(E27>=9,"A",IF(E27>=7,"B",IF(E27>=5,"C+",IF(E27>=3,"C-","D")))) -> D | F28: =IF(F27>=9,"A",IF(F27>=7,"B",IF(F27>=5,"C+",IF(F27>=3,"C-","D")))) -> D
A29: =Language!C65 -> Trabajo propuesto para matrícula de honor | C29: =RubricExaminer1!G37 -> FALSE | D29: =RubricExaminer2!G37 -> FALSE | E29: =RubricExaminer3!G37 -> FALSE
A31: =Language!C68 -> Evaluador/a 1. Observaciones y recomendaciones:
A32: =RubricExaminer1!A40
A33: =Language!C69 -> Evaluador/a 2. Observaciones y recomendaciones:
A34: =RubricExaminer2!A40
A35: =Language!C70 -> Evaluador/a 3. Observaciones y recomendaciones:
A36: =RubricExaminer3!A40

Sheet StudentReport
D1: =RubricTutor!D1 -> Bachelor's degree in Techniques for Software Application Development
D2: =CONCATENATE(Language!C74, RubricTutor!D7) -> Informe de evaluación final del Trabajo Final - Semestre 2025-1
A4: =Language!C5 -> Nombre del/de la estudiante: | D4: =RubricTutor!D4
A5: =Language!C6 -> Título del trabajo: | D5: =RubricTutor!D5
A6: =Language!C7 -> Programa: | D6: =RubricTutor!D6 -> Bachelor's degree in Techniques for Software Application Development
A7: =Language!C9 -> Tutor/a: | D7: =RubricTutor!D8
D9: =Language!C25 -> Peso | E9: =Language!C72 -> Nota numérica | F9: =Language!C73 -> Nota categórica | H9: =Language!C71 -> Tribunal de evaluación
A10: =Language!C14 -> Evaluación del tutor/a | D10: 0.4 | E10: =K37 -> 0 | F10: =IF(E10>=9,"A",IF(E10>=7,"B",IF(E10>=5,"C+",IF(E10>=3,"C-","D")))) -> D | H10: =RubricTutor!D9
A11: =Language!C15 -> Evaluación del tribunal | D11: 0.6 | E11: =K61 -> 0 | F11: =IF(E11>=9,"A",IF(E11>=7,"B",IF(E11>=5,"C+",IF(E11>=3,"C-","D")))) -> D | H11: =RubricTutor!D10
A12: =Language!C16 -> Evaluación final | E12: =ROUND(E10*D10+E11*D11,1) -> 0 | F12: =IF(E12>=9,"A",IF(E12>=7,"B",IF(E12>=5,"C+",IF(E12>=3,"C-","D")))) -> D | H12: =RubricTutor!D11
A14: A | C14: B | E14: C+ | G14: C- | I14: D
A15: 10 | B15: 9 | C15: 8 | D15: 7 | E15: 6 | F15: 5 | G15: 4 | H15: 3 | I15: 2 | J15: 1 | K15: 0
A17: =Language!C14 -> Evaluación del tutor/a | K17: =Language!C17 -> Evaluación
A18: =Language!C29 -> Actitud del/de la estudiante
A19: =Language!C30 -> Grado de autonomía, creatividad, iniciativa, receptividad a la crítica, y buena comunicación con el tutor/a | K19: =IF(ISNUMBER(RubricTutor!Q18),ROUND(RubricTutor!Q18,2),RubricTutor!Q18) -> D
A20: =Language!C31 -> Aspectos metodológicos
A21: =Language!C32 -> Definición de unos objetivos claros, concretos, realistas y adecuados | K21: =IF(ISNUMBER(RubricTutor!Q20),ROUND(RubricTutor!Q20,2),RubricTutor!Q20) -> D
A22: =Language!C33 -> Definición de la metodología, planificación temporal y de recursos | K22: =IF(ISNUMBER(RubricTutor!Q21),ROUND(RubricTutor!Q21,2),RubricTutor!Q21) -> D
A23: =Language!C34 -> Especificación y diseño
A24: =Language!C35 -> Estudio previo e identificación de los aspectos relevantes del problema y de su solución (e.g. estado del arte, estudio de mercado) | K24: =IF(ISNUMBER(RubricTutor!Q23),ROUND(RubricTutor!Q23,2),RubricTutor!Q23) -> D
A25: =Language!C36 -> Análisis de requerimientos | K25: =IF(ISNUMBER(RubricTutor!Q24),ROUND(RubricTutor!Q24,2),RubricTutor!Q24) -> D
A26: =Language!C37 -> Diseño adecuado de la propuesta | K26: =IF(ISNUMBER(RubricTutor!Q25),ROUND(RubricTutor!Q25,2),RubricTutor!Q25) -> D
A27: =Language!C38 -> Elección de herramientas, tecnologías y fuentes de información adecuadas para el desarrollo del trabajo | K27: =IF(ISNUMBER(RubricTutor!Q26),ROUND(RubricTutor!Q26,2),RubricTutor!Q26) -> D
A28: =Language!C39 -> Grado de análisis y tratamiento del impacto ético-social, de sostenibilidad y de diversidad del trabajo | K28: =IF(ISNUMBER(RubricTutor!Q27),ROUND(RubricTutor!Q27,2),RubricTutor!Q27) -> D
A29: =Language!C40 -> Ejecución e implementación del proyecto
A30: =Language!C41 -> Seguimiento de la planificación y capacidad de adaptación | K30: =IF(ISNUMBER(RubricTutor!Q29),ROUND(RubricTutor!Q29,2),RubricTutor!Q29) -> D
A31: =Language!C42 -> Calidad de la contribución técnica y/o científica del proyecto. Calidad de la solución/producto en desarrollo/obtenido | K31: =IF(ISNUMBER(RubricTutor!Q30),ROUND(RubricTutor!Q30,2),RubricTutor!Q30) -> D
A32: =Language!C43 -> Grado de innovación de la solución presentada | K32: =IF(ISNUMBER(RubricTutor!Q31),ROUND(RubricTutor!Q31,2),RubricTutor!Q31) -> D
A33: =Language!C44 -> Conclusiones y discusión de los resultados | K33: =IF(ISNUMBER(RubricTutor!Q32),ROUND(RubricTutor!Q32,2),RubricTutor!Q32) -> D
A34: =Language!C45 -> Aspectos formales de la memoria
A35: =Language!C46 -> Redacción adecuada, utilización flexible de un lenguaje inclusivo, y organización clara y correcta del contenido | K35: =IF(ISNUMBER(RubricTutor!Q34),ROUND(RubricTutor!Q34,2),RubricTutor!Q34) -> D
A36: =Language!C47 -> Fuentes de información y referencias bibliográficas | K36: =IF(ISNUMBER(RubricTutor!Q35),ROUND(RubricTutor!Q35,2),RubricTutor!Q35) -> D
A37: =Language!C18 -> Evaluación final del tutor/a | K37: =IF(ISNUMBER(RubricTutor!Q37),ROUND(RubricTutor!Q37,1),RubricTutor!Q37) -> 0
A41: =Language!C15 -> Evaluación del tribunal | K41: =Language!C17 -> Evaluación
A42: =Language!C31 -> Aspectos metodológicos
A43: =Language!C32 -> Definición de unos objetivos claros, concretos, realistas y adecuados | K43: =DefenseSummary!G9 -> D
A44: =Language!C33 -> Definición de la metodología, planificación temporal y de recursos | K44: =DefenseSummary!G10 -> D
A45: =Language!C34 -> Especificación y diseño
A46: =Language!C35 -> Estudio previo e identificación de los aspectos relevantes del problema y de su solución (e.g. estado del arte, estudio de mercado) | K46: =DefenseSummary!G12 -> D
A47: =Language!C36 -> Análisis de requerimientos | K47: =DefenseSummary!G13 -> D
...

Sheet AssessmentCriteria
B1: Actitud del/de la estudiante | E1: Actitud de l'estudiant | H1: Student's attitude
B2: Grado de autonomía, creatividad, iniciativa, receptividad a la crítica, comunicación con el tutor/a | E2: Grau d'autonomia, creativitat, iniciativa, receptivitat a la crítica, i bona comunicació amb el tutor/a | H2: Autonomy, creativity, initiative, receptivity to criticism, and good communication with the supervisor
A3: A | B3: • El/La estudiante ha trabajado de forma autónoma, demostrando iniciativa y creatividad, minimizando la dependencia del tutor/a para avanzar con el trabajo • La comunicación con el tutor/a ha sido fluida y el/la estudiante ha tenido una buena receptividad a la crítica • El/La estudiante ha sabido discutir las decisiones tomadas con el tutor/a de forma coherente y razonada, demostrando una capacidad de comprender, analizar y solucionar problemas propia del nivel académico o profesional esperado | D3: A | E3: • L'estudiant ha treballat de forma autònoma, demostrant iniciativa i creativitat, minimitzant la dependència del tutor/a per avançar amb el treball • La comunicació amb el tutor/a ha estat fluïda i l'estudiant ha tingut una bona receptivitat a la crítica • L'estudiant ha sabut discutir les decisions preses amb el tutor/a de forma coherent i raonada, demostrant una capacitat de comprendre, analitzar i solucionar problemes pròpis del nivell acadèmic o professional esperat | G3: A | H3: • The student has worked autonomously, showing initiative and creativity, minimizing dependency on the supervisor to advance with the project • Communication with the supervisor has been fluent and the student has had a good receptivity to criticism • The student has discussed with the supervisor the decisions made in a coherent and reasoned manner, demonstrating an ability to understand, analyze and solve problems typical of the expected academic or professional level
A4: B | B4: • El/La estudiante ha trabajado de forma autónoma en gran medida, demostrando cierta iniciativa y algo de creatividad • La comunicación con el tutor/a ha sido fluida y el/la estudiante ha tenido una buena receptividad a la crítica • El/La estudiante ha sabido discutir las decisiones tomadas con el tutor/a de forma coherente y razonada, demostrando una capacidad de comprender, analizar y solucionar problemas propia del nivel académico o profesional esperado | D4: B | E4: • L'estudiant ha treballat de forma autònoma en gran mesura, demostrant certa iniciativa i una mica de creativitat • La comunicació amb el tutor/a ha estat fluïda i l'estudiant ha tingut una bona receptivitat a la crítica • L'estudiant ha sabut discutir les decisions preses amb el tutor/a de forma coherent i raonada, demostrant una capacitat de comprendre, analitzar i solucionar problemes pròpia del nivell acadèmic o professional esperat | G4: B | H4: • The student has worked autonomously to a great extent, showing some initiative and some creativity • Communication with the supervisor has been fluent and the student has had a good receptivity to criticism • The student has discussed the decisions made with the supervisor in a coherent and reasoned manner, demonstrating an ability to understand, analyze and solve problems typical of the expected academic or professional level
A5: C+ | B5: • El/La estudiante ha sido algo dependiente del tutor/a, demostrando cierta iniciativa y algo de creatividad • La comunicación con el tutor/a ha sido fluida y el/la estudiante ha tenido una buena receptividad a la crítica • Aunque no siempre, en general, el/la estudiante ha sabido discutir las decisiones tomadas con el tutor/a de forma coherente y razonada, demostrando una capacidad de comprender, analizar y solucionar problemas propia del nivel académico o profesional esperado. Hay espacio para mejorar | D5: C+ | E5: • L'estudiant ha estat una mica depenent de el tutor/a, demostrant certa iniciativa i una mica de creativitat • La comunicació amb el tutor/a ha estat fluïda i l'estudiant ha tingut una bona receptivitat a la crítica • Encara que no sempre, en general, l'estudiant ha sabut discutir les decisions preses amb el tutor/a de forma coherent i raonada, demostrant una capacitat de comprendre, analitzar i solucionar problemes pròpia del nivell acadèmic o professional esperat. Hi ha espai per millorar | G5: C+ | H5: • The student has been somehow dependent on the supervisor, showing some initiative and some creativity • Communication with the supervisor has been fluid and the student has had a good receptivity to criticism • Although not always, in general, the student has been able to discuss the decisions made with the supervisor in a coherent and reasoned manner, demonstrating an ability to understand, analyze and solve problems typical of the expected academic or professional level. There is room for improvement
A6: C- | B6: Alguna de las siguientes afirmaciones describen al/a la estudiante: • El/La estudiante ha tenido una gran dependencia del tutor/a, sin demostrar iniciativa o creatividad • La comunicación con el tutor/a no ha sido fluida y al/a la estudiante le cuesta aceptar la crítica • El/La estudiante no ha sabido discutir las decisiones tomadas de forma coherente y razonada • El/La estudiante no demuestra una capacidad de solucionar problemas propios del nivel académico o profesional esperado | D6: C- | E6: Alguna de les següents afirmacions descriuen a l'estudiant: • L'estudiant ha tingut una gran dependència de tutor/a, sense demostrar iniciativa o creativitat • La comunicació amb el tutor/a no ha estat fluida i a l'estudiant li costa acceptar la crítica • L'estudiant no ha sabut discutir les decisions preses de forma coherent i raonada • L'estudiant no demostra una capacitat de solucionar problemes propis del nivell acadèmic o professional esperat | G6: C- | H6: One or more of the following statements describe the student: • The student has had a great dependency on the supervisor, without showing initiative or creativity • Communication with the supervisor has not been fluent and the student finds it difficult to accept criticism • The student has not shown the ability to discuss the decisions made in a coherent and reasoned way • The student does not demonstrate the ability to solve problems of the expected academic or professional level
A7: D | B7: Todas las afirmaciones que se exponen a continuación describen al/a la estudiante: • El/La estudiante ha tenido una gran dependencia del tutor/a, sin demostrar iniciativa o creatividad • La comunicación con el tutor/a no ha sido fluida y al/a la estudiante le cuesta aceptar la crítica • El/La estudiante no ha sabido discutir las decisiones tomadas de forma coherente y razonada • El/La estudiante no demuestra una capacidad de solucionar problemas propios del nivel académico o profesional esperado | D7: D | E7: Totes les afirmacions que s'exposen a continuació descriuen a l'estudiant: • L'estudiant ha tingut una gran dependència de tutor/a, sense demostrar iniciativa o creativitat • La comunicació amb el tutor/a no ha estat fluida i a l'estudiant li costa acceptar la crítica • L'estudiant no ha sabut discutir les decisions preses de forma coherent i raonada. • L'estudiant no demostra una capacitat de solucionar problemes propis del nivell acadèmic o professional esperat | G7: D | H7: All of the statements below describe the student: • The student has had a great dependency on the supervisor, without showing initiative or creativity • Communication with the supervisor has not been fluent and the student finds it difficult to accept criticism • The student has not shown the ability to discuss the decisions made in a coherent and reasoned way • The student does not demonstrate the ability to solve problems of the expected academic or professional level
B9: Aspectos metodológicos | E9: Aspectes metodològics | H9: Methodological aspects
B10: Definición de unos objetivos claros, concretos, realistas y adecuados | E10: Definició d'uns objectius clars, concrets, realistes i adequats | H10: Definition of clear, specific, realistic and adequate objectives
A11: A | B11: • Los objetivos son adecuados al contexto del trabajo • Cada objetivo es claro y evaluable • Los objetivos son realistas • Los objetivos están priorizados | D11: A | E11: • Els objectius són adequats al context del treball • Cada objectiu és clar i avaluable • Els objectius són realistes • Els objectius estan prioritzats | G11: A | H11: • The objectives are appropriate to the context of the project • Each objective is clear and measurable • The objectives are realistic • The objectives have been assigned a priority level
A12: B | B12: Los objetivos son adecuados al contexto del trabajo y responden a la mayoría de los siguientes puntos, pero no todos: • Cada objetivo es claro y evaluable • Los objetivos son realistas • Los objetivos están priorizados | D12: B | E12: Els objectius són adequats al context del treball i responen a la majoria dels següents punts, però no tots: • Cada objectiu és clar i avaluable • Els objectius són realistes • Els objectius estan prioritzats | G12: B | H12: The objectives are appropriate to the context of the work and answer most of the following points, but not all: • Each objective is clear and measurable • The objectives are realistic • The objectives have been assigned a priority level
A13: C+ | B13: Los objetivos son adecuados al contexto del trabajo, pero no responden a la mayoría de los siguientes puntos: • Cada objetivo es claro y evaluable • Los objetivos son realistas • Los objetivos están priorizados | D13: C+ | E13: Els objectius són adequats al context del treball, però no responen a la majoria dels següents punts: • Cada objectiu és clar i avaluable • Els objectius són realistes • Els objectius estan prioritzats | G13: C+ | H13: The objectives are appropriate to the context of the work, but do not respond to most of the following points: • Each objective is clear and measurable • The objectives are realistic • The objectives have been assigned a priority level
A14: C- | B14: • Alguno de los objetivos definidos no es pertinente en el contexto del trabajo • Varios de los objetivos definidos no son claros ni evaluables | D14: C- | E14: • Algun dels objectius definits no és pertinent en el context del treball • Diversos dels objectius definits no són clars ni avaluables | G14: C- | H14: • Some of the defined objectives are not relevant in the context of the work • Several of the defined objectives are not clear or measurable
A15: D | B15: • No se ha definido una lista de objetivos, o los objetivos no son adecuados en el contexto del trabajo | D15: D | E15: • No s'ha definit una llista d'objectius, o els objectius no són adequats en el context del treball | G15: D | H15: • A list of objectives has not been defined, or the objectives are not appropriate in the context of the project
B17: Definición de la metodología, planificación temporal y de recursos | E17: Definició de la metodologia, planificació temporal i de recursos | H17: Methodology, schedule and resource planning
A18: A | B18: • Se ha escogido una metodología adecuada para alcanzar los objetivos propuestos. Se ha adaptado la metodología a las necesidades del proyecto • Se han identificado las tareas necesarias para conseguir los objetivos propuestos • La duración estimada para cada tarea es adecuada • La planificación global del trabajo es realista • Se ha tenido en cuenta el nivel de conocimiento y experiencia al establecer la duración de las tareas • El calendario tiene en cuenta la dedicación esperada, la disponibilidad de recursos y las fechas especiales del calendario (festivos, puentes, vacaciones,...) • Se incluye un diagrama de Gantt o similar • Si es apropiado, se han detallado los costes económicos asociados • La planificación considera explícitamente las actividades pertinentes de carácter no técnico (redacción de la memoria, elaboración de la presentación,...) • Se ha hecho un análisis de riesgos que tenga en cuenta de forma exhaustiva posibles eventualidades surgidas al desarrollar el proyecto, así como establecer medidas mitigadoras y correctivas adecuadas | D18: A | E18: • S'ha escollit una metodologia adequada per assolir els objectius proposats. S'ha adaptat la metodologia a les necessitats del projecte • S'han identificat les tasques necessàries per aconseguir els objectius proposats • La durada estimada per a cada tasca és adequada • La planificació global del treball és realista • S'ha tingut en compte el nivell de coneixement i experiència a l'establir la durada de les tasques • El calendari té en compte la dedicació esperada, la disponibilitat de recursos i les dates especials del calendari (festius, ponts, vacances, ...) • S'inclou un diagrama de Gantt o similar • Si és apropiat, s'han detallat els costos econòmics associats • La planificació considera explícitament les activitats pertinents de caràcter no tècnic (redacció de la memòria, elaboració de la presentació, ...) • S'ha fet una anàlisi de riscos que tingui en compte de manera exhaustiva possibles eventualitats sorgides al desenvolupar el projecte, així com establir mesures mitigadores i correctives adequades | G18: A | H18: • An appropriate methodology has been chosen to achieve the proposed objectives. The methodology has been adapted to the needs of the project • The tasks necessary to achieve the proposed objectives have been identified • The estimated duration for each task is appropriate • The overall work planning is realistic • The level of knowledge and experience has been taken into account when establishing the duration of the tasks • The schedule takes into account the expected dedication, the availability of resources and the special dates of the calendar (e.g. holidays) • A Gantt chart or similar is included • If appropriate, the associated economic costs have been detailed • The planning explicitly considers the pertinent activities of a non-technical nature (e.g. writing the report, preparing the presentation) • A risk analysis has been carried out that exhaustively takes into account possible contingencies that may arise when developing the project, as well as establishing appropriate mitigating and corrective measures
A19: B | B19: • Se ha escogido una metodología adecuada para alcanzar los objetivos propuestos. No se ha especificado cómo se adaptará la metodología a las necesidades del proyecto • Se han identificado las tareas necesarias para conseguir los objetivos propuestos • La duración estimada para cada tarea es adecuada • La planificación es realista • Se ha tenido en cuenta el nivel de conocimiento y experiencia al establecer la duración de las tareas • El calendario establecido es mejorable ya que no tiene en cuenta la dedicación esperada, la disponibilidad de recursos o las fechas especiales del calendario (festivos, puentes, vacaciones,...) • Se incluye un diagrama de Gantt o similar • Si es apropiado, se han detallado los costes económicos asociados • La planificación considera explícitamente las actividades pertinentes de carácter no técnico (redacción de la memoria, elaboración de la presentación,...) • Siendo necesario, no se ha hecho un análisis de riesgos adecuado que tenga en cuenta de forma exhaustiva posibles eventualidades surgidas al desarrollar el proyecto | D19: B | E19: • S'ha escollit una metodologia adequada per assolir els objectius proposats. No s'ha especificat com s'adaptarà la metodologia a les necessitats del projecte • S'han identificat les tasques necessàries per aconseguir els objectius proposats • La durada estimada per a cada tasca és adequada • La planificació és realista • S'ha tingut en compte el nivell de coneixement i experiència a l'establir la durada de les tasques • El calendari establert és millorable ja que no té en compte la dedicació esperada, la disponibilitat de recursos o les dates especials del calendari (festius, ponts, vacances, ...) • S'inclou un diagrama de Gantt o similar • Si és apropiat, s'han detallat els costos econòmics associats • La planificació considera explícitament les activitats pertinents de caràcter no tècnic (redacció de la memòria, elaboració de la presentació, ...) • Sent necessari, no s'ha fet una anàlisi de riscos adequat que tingui en compte de manera exhaustiva possibles eventualitats sorgides al desenvolupar el projecte | G19: B | H19: • An appropriate methodology has been chosen to achieve the proposed objectives. It has not been specified how the methodology will be adapted to the needs of the project • The tasks necessary to achieve the proposed objectives have been identified. • The estimated duration for each task is appropriate • Planning is realistic • The level of knowledge and experience has been taken into account when establishing the duration of the tasks • The established schedule can be improved since it does not take into account the expected dedication, the availability of resources or the special dates of the calendar (e.g. holidays) • A Gantt chart or similar is included • If appropriate, the associated economic costs have been detailed • The planning explicitly considers the pertinent activities of a non-technical nature (e.g. writing the report, preparing the presentation) • Being necessary, an adequate risk analysis has not been carried out that exhaustively takes into account possible contingencies that may arise when developing the project.
A20: C+ | B20: • Se ha escogido una metodología mínimamente adecuada para alcanzar los objetivos propuestos • Se han identificado las tareas básicas para conseguir los objetivos propuestos • La planificación es realista • Se incluye un diagrama de Gantt o similar | D20: C+ | E20: • S'ha escollit una metodologia mínimament adequada per assolir els objectius proposats • S'han identificat les tasques bàsiques per aconseguir els objectius proposats • La planificació és realista • S'inclou un diagrama de Gantt o similar | G20: C+ | H20: • A minimally adequate methodology has been chosen to achieve the proposed objectives • The basic tasks have been identified to achieve the proposed objectives • Schedule is realistic • A Gantt chart or similar is included
A21: C- | B21: • Se ha escogido una metodología mínimamente adecuada para alcanzar los objetivos propuestos • Se han identificado las tareas básicas para conseguir los objetivos propuestos • No se ha hecho una planificación de tareas | D21: C- | E21: • S'ha escollit una metodologia mínimament adequada per assolir els objectius proposats • S'han identificat les tasques bàsiques per aconseguir els objectius proposats • No s'ha fet una planificació de tasques | G21: C- | H21: • A minimally adequate methodology has been chosen to achieve the proposed objectives. • The basic tasks have been identified to achieve the proposed objectives • Task planning has not been done
A22: D | B22: • No se ha escogido una metodología mínimamente adecuada para alcanzar los objetivos propuestos • No se han identificado las tareas básicas para conseguir los objetivos propuestos | D22: D | E22: • No s'ha escollit una metodologia mínimament adequada per assolir els objectius proposats • No s'han identificat les tasques bàsiques per aconseguir els objectius proposats | G22: D | H22: • A minimally adequate methodology has not been chosen to achieve the proposed objectives • The basic tasks to achieve the proposed objectives have not been identified
B24: Especificación y diseño | E24: Especificació i disseny | H24: Specification and design
B25: Estudio previo e identificación de los aspectos relevantes del problema y de su solución (e.g. estado del arte, estudio de mercado) | E25: Estudi previ i identificació dels aspectes rellevants del problema i de la seva solució (e.g. estat de l'art, estudi de mercat) | H25: Perliminary study and identification of relevant aspects of the problem and its solution (e.g. state of the art, market study)
A26: A | B26: • Se identifican todos los aspectos relevantes del problema • Se evalúan diversas alternativas para solucionarlo • Se estudian en profundidad otros trabajos o soluciones propuestas por otros autores para encarar el problema planteado. Entre ellos se han tenido en cuenta los trabajos más actuales y más relevantes dentro del área de estudio • Se describe una solución adecuada al problema planteado | D26: A | E26: • S'identifiquen tots els aspectes rellevants del problema • S'avaluen diverses alternatives per solucionar el problema • S'estudien en profunditat altres treballs o solucions proposades per altres autors per encarar el problema plantejat. Entre ells s'han tingut en compte els treballs més actuals i més rellevants dins l'àrea d'estudi • Es descriu una solució adequada al problema plantejat | G26: A | H26: • All relevant aspects of the problem have been identified • Several alternatives to solve the problem have been evaluated • Other work or solutions proposed by other authors to deal with the problem are studied in depth. Among them, the most updated and most relevant works within the study area have been taken into account. • An appropriate solution to the problem has been properly described
A27: B | B27: • Se identifican los aspectos más relevantes del problema • Se evalúan las alternativas más destacadas para solucionarlo • Se estudian otros trabajos o soluciones propuestas por otros autores para encarar el problema planteado. Sin embargo, no se tienen en cuenta los trabajos más actuales o más relevantes dentro del área de estudio. • Se describe una solución adecuada al problema planteado | D27: B | E27: • S'identifiquen els aspectes més rellevants del problema • S'avaluen les alternatives més destacades per solucionar el problema • S'estudien altres treballs o solucions proposades per altres autors per encarar el problema plantejat. No obstant això, no es tenen en compte els treballs més actuals o més rellevants dins l'àrea d'estudi. • Es descriu una solució adequada al problema plantejat | G27: B | H27: • Only the most relevant aspects of the problem have been identified • Only the most outstanding alternatives to solve the problem have been evaluated • Other work or solutions proposed by other authors are studied to deal with the problem. However, the most updated or most relevant works within the study area are not taken into account • An appropriate solution to the problem has been properly described
A28: C+ | B28: • Se identifican los aspectos básicos del problema • Se evalúan algunas alternativas para solucionarlo • Se describe una solución bàsica al problema planteado | D28: C+ | E28: • S'identifiquen els aspectes bàsics del problema • S'avaluen algunes alternatives per solucionar-lo • Es descriu una solució bàsica al problema plantejat | G28: C+ | H28: • The basic aspects of the problem have been identified • Only few alternatives have been evaluated to solve it • A basic solution to the problem has been described
A29: C- | B29: • No se identifican los aspectos básicos del problema • Se describe una solución básica al problema planteado | D29: C- | E29: • No s'identifiquen els aspectes bàsics del problema • Es descriu una solució bàsica al problema plantejat | G29: C- | H29: • The basic aspects of the problem have not been identified • A basic solution to the problem has been described
A30: D | B30: • No se identifican los aspectos básicos del problema • No se describe una solución básica al problema planteado | D30: D | E30: • No s'identifiquen els aspectes bàsics del problema • No es descriu una solució bàsica al problema plantejat | G30: D | H30: • The basic aspects of the problem have not been identified • A basic solution to the problem has not been described
B32: Análisis de requerimientos | E32: Anàlisi de requeriments | H32: Requirement analysis
